구독하기 테스트

가입하기로 3개의 계정을 만든다

postman실행

http://localhost:8080/api/subscribe/2로 POST요청

{
"code": 1,
"message": "구독하기 성공",
"data": null
}

리턴받음

DB에서 select \* from subscribe;조회시

![Visual Studio Code](/img/%EA%B5%AC%EB%8F%85%ED%85%8C%EC%8A%A4%ED%8A%B8.png)

이렇게 뜸

2번 구독한 상태에서 또

http://localhost:8080/api/subscribe/2날리면 500 에러 뜸

(Subscribe.java)

```
@Table(uniqueConstraints= {
		@UniqueConstraint(
				name="subscribe_uk",
				columnNames= {"fromUserId","toUserId"}//실제데이터베이스의 컬럼명

				)
})
public class Subscribe {
```

유니크 설정되있으므로

500에러로 출력하지말고

(CustomApiException.java)

```
public class CustomApiException extends RuntimeException{

	private static final long serialVersionUID = -807520916259076805L;

	public CustomApiException(String message) {
		super(message);
	}

}

```

errorMap은 지워주었따. 메시지만 리턴해주면 될것같아서

(에러가 여러개로 뜰일이 없을 것 같으므로)

---

(SubscribeService.java)

```
	@Transactional // insert하거나 delete하는거니까 DB에 영향을 주니까 @Transactional 사용
	public void 구독하기(int fromUserId, int toUserId) {
		try {
			subscribeRepository.mSubscribe(fromUserId,toUserId); //mSubscribe 여기서 m은 내가 만들었다의 약어
		}catch(Exception e) {
			throw new CustomApiException("이미 구독을 하였습니다.");
		}

	}

    @Transactional
	public void 구독취소하기(int fromUserId, int toUserId) {
		subscribeRepository.mUnSubscribe(fromUserId, toUserId);
	}
```

try catch로 예외처리 해주었음.

구독취소하기는 삭제하는거니까 오류날일이 없어서 try catch 안걸어줬음.

그리고 나서

(ControllerExceptionHandler.java)

```
@ExceptionHandler(CustomApiException.class) // RuntimeException을 발생하는 모든 exception을 이 함수가 가로챔
	public ResponseEntity<?> apiException(CustomApiException e) {
		System.out.println("나실행됨?");
		return new ResponseEntity<>(new CMRespDto<>(-1,e.getMessage(),null),HttpStatus.BAD_REQUEST);
	}
```

CustomApiException를 핸들러에서 낚아채서 실행

errorMap은 없으니까 null로 파라미터에 던짐.

---

이제 다시 구독했던사람을 또 구독해보자

(SubscribeService.java)

http://localhost:8080/api/subscribe/2

{
"code": -1,
"message": "이미 구독을 하였습니다.",
"data": null
}

이렇게 리턴됨.
